Workbook

Sheet SRL beregninger
A1: TRL and IRL data from SBS | N1: Normalised TRL and IRL
A2: Component Ids | C2: 1 | D2: 2 | E2: 3 | F2: 4 | G2: 5 | H2: 6 | I2: 7 | J2: 8 | K2: 9 | L2: 10 | N2: Component Ids | P2: 1 | Q2: 2 | R2: 3 | S2: 4 | T2: 5 | U2: 6 | V2: 7 | W2: 8 | X2: 9 | Y2: 10
B3: TRL | C3: 4 | D3: 4 | E3: 5 | F3: 7 | G3: 5 | H3: 5 | I3: 4 | J3: 3 | K3: 5 | L3: 4 | O3: TRL | P3: =1/9*C3 -> 0.44444444 | Q3: =1/9*D3 -> 0.44444444 | R3: =1/9*E3 -> 0.55555556 | S3: =1/9*F3 -> 0.77777778 | T3: =1/9*G3 -> 0.55555556 | U3: =1/9*H3 -> 0.55555556 | V3: =1/9*I3 -> 0.44444444 | W3: =1/9*J3 -> 0.33333333 | ... Y3: =1/9*L3 -> 0.44444444 | AB3: Component SRL
A4: IRL | B4: 1 | C4: 9 | D4: 0 | E4: 0 | F4: 0 | G4: 0 | H4: 0 | I4: 1 | J4: 0 | K4: 0 | L4: 0 | N4: IRL | O4: 1 | P4: =1/9*C4 -> 1 | Q4: =1/9*D4 -> 0 | R4: =1/9*E4 -> 0 | S4: =1/9*F4 -> 0 | T4: =1/9*G4 -> 0 | U4: =1/9*H4 -> 0 | V4: =1/9*I4 -> 0.11111111 | W4: =1/9*J4 -> 0 | ... Y4: =1/9*L4 -> 0 | AA4: {=+SUM($P$3:$Y$3*P4:Y4)} -> 0.49382716 | AB4: =+AA4/COUNTIF(P4:Y4,">0") -> 0.24691358 | AC4: 1
B5: 2 | C5: 0 | D5: 9 | E5: 0 | F5: 0 | G5: 0 | H5: 0 | I5: 0 | J5: 1 | K5: 0 | L5: 0 | O5: 2 | P5: =1/9*C5 -> 0 | Q5: =1/9*D5 -> 1 | R5: =1/9*E5 -> 0 | S5: =1/9*F5 -> 0 | T5: =1/9*G5 -> 0 | U5: =1/9*H5 -> 0 | V5: =1/9*I5 -> 0 | W5: =1/9*J5 -> 0.11111111 | ... Y5: =1/9*L5 -> 0 | AA5: {=+SUM($P$3:$Y$3*P5:Y5)} -> 0.48148148 | AB5: =+AA5/COUNTIF(P5:Y5,">0") -> 0.24074074 | AC5: 2
B6: 3 | C6: 0 | D6: 0 | E6: 9 | F6: 0 | G6: 0 | H6: 0 | I6: 0 | J6: 1 | K6: 0 | L6: 0 | O6: 3 | P6: =1/9*C6 -> 0 | Q6: =1/9*D6 -> 0 | R6: =1/9*E6 -> 1 | S6: =1/9*F6 -> 0 | T6: =1/9*G6 -> 0 | U6: =1/9*H6 -> 0 | V6: =1/9*I6 -> 0 | W6: =1/9*J6 -> 0.11111111 | ... Y6: =1/9*L6 -> 0 | AA6: {=+SUM($P$3:$Y$3*P6:Y6)} -> 0.59259259 | AB6: =+AA6/COUNTIF(P6:Y6,">0") -> 0.2962963 | AC6: 3
B7: 4 | C7: 0 | D7: 0 | E7: 0 | F7: 9 | G7: 1 | H7: 1 | I7: 0 | J7: 0 | K7: 0 | L7: 0 | O7: 4 | P7: =1/9*C7 -> 0 | Q7: =1/9*D7 -> 0 | R7: =1/9*E7 -> 0 | S7: =1/9*F7 -> 1 | T7: =1/9*G7 -> 0.11111111 | U7: =1/9*H7 -> 0.11111111 | V7: =1/9*I7 -> 0 | W7: =1/9*J7 -> 0 | ... Y7: =1/9*L7 -> 0 | AA7: {=+SUM($P$3:$Y$3*P7:Y7)} -> 0.90123457 | AB7: =+AA7/COUNTIF(P7:Y7,">0") -> 0.30041152 | AC7: 4
B8: 5 | C8: 0 | D8: 0 | E8: 0 | F8: 1 | G8: 9 | H8: 1 | I8: 0 | J8: 0 | K8: 0 | L8: 0 | O8: 5 | P8: =1/9*C8 -> 0 | Q8: =1/9*D8 -> 0 | R8: =1/9*E8 -> 0 | S8: =1/9*F8 -> 0.11111111 | T8: =1/9*G8 -> 1 | U8: =1/9*H8 -> 0.11111111 | V8: =1/9*I8 -> 0 | W8: =1/9*J8 -> 0 | ... Y8: =1/9*L8 -> 0 | AA8: {=+SUM($P$3:$Y$3*P8:Y8)} -> 0.7037037 | AB8: =+AA8/COUNTIF(P8:Y8,">0") -> 0.2345679 | AC8: 5
B9: 6 | C9: 0 | D9: 0 | E9: 0 | F9: 1 | G9: 1 | H9: 9 | I9: 0 | J9: 0 | K9: 1 | L9: 1 | O9: 6 | P9: =1/9*C9 -> 0 | Q9: =1/9*D9 -> 0 | R9: =1/9*E9 -> 0 | S9: =1/9*F9 -> 0.11111111 | T9: =1/9*G9 -> 0.11111111 | U9: =1/9*H9 -> 1 | V9: =1/9*I9 -> 0 | W9: =1/9*J9 -> 0 | ... Y9: =1/9*L9 -> 0.11111111 | AA9: {=+SUM($P$3:$Y$3*P9:Y9)} -> 0.81481481 | AB9: =+AA9/COUNTIF(P9:Y9,">0") -> 0.16296296 | AC9: 6
B10: 7 | C10: 1 | D10: 0 | E10: 0 | F10: 0 | G10: 0 | H10: 0 | I10: 9 | J10: 0 | K10: 1 | L10: 0 | O10: 7 | P10: =1/9*C10 -> 0.11111111 | Q10: =1/9*D10 -> 0 | R10: =1/9*E10 -> 0 | S10: =1/9*F10 -> 0 | T10: =1/9*G10 -> 0 | U10: =1/9*H10 -> 0 | V10: =1/9*I10 -> 1 | W10: =1/9*J10 -> 0 | ... Y10: =1/9*L10 -> 0 | AA10: {=+SUM($P$3:$Y$3*P10:Y10)} -> 0.55555556 | AB10: =+AA10/COUNTIF(P10:Y10,">0") -> 0.18518519 | AC10: 7
B11: 8 | C11: 0 | D11: 1 | E11: 1 | F11: 0 | G11: 0 | H11: 0 | I11: 0 | J11: 9 | K11: 1 | L11: 0 | O11: 8 | P11: =1/9*C11 -> 0 | Q11: =1/9*D11 -> 0.11111111 | R11: =1/9*E11 -> 0.11111111 | S11: =1/9*F11 -> 0 | T11: =1/9*G11 -> 0 | U11: =1/9*H11 -> 0 | V11: =1/9*I11 -> 0 | W11: =1/9*J11 -> 1 | ... Y11: =1/9*L11 -> 0 | AA11: {=+SUM($P$3:$Y$3*P11:Y11)} -> 0.50617284 | AB11: =+AA11/COUNTIF(P11:Y11,">0") -> 0.12654321 | AC11: 8
B12: 9 | C12: 0 | D12: 0 | E12: 0 | F12: 0 | G12: 0 | H12: 1 | I12: 1 | J12: 1 | K12: 9 | L12: 0 | O12: 9 | P12: =1/9*C12 -> 0 | Q12: =1/9*D12 -> 0 | R12: =1/9*E12 -> 0 | S12: =1/9*F12 -> 0 | T12: =1/9*G12 -> 0 | U12: =1/9*H12 -> 0.11111111 | V12: =1/9*I12 -> 0.11111111 | W12: =1/9*J12 -> 0.11111111 | ... Y12: =1/9*L12 -> 0 | AA12: {=+SUM($P$3:$Y$3*P12:Y12)} -> 0.7037037 | AB12: =+AA12/COUNTIF(P12:Y12,">0") -> 0.17592593 | AC12: 9
B13: 10 | C13: 0 | D13: 0 | E13: 0 | F13: 0 | G13: 0 | H13: 1 | I13: 0 | J13: 0 | K13: 0 | L13: 9 | O13: 10 | P13: =1/9*C13 -> 0 | Q13: =1/9*D13 -> 0 | R13: =1/9*E13 -> 0 | S13: =1/9*F13 -> 0 | T13: =1/9*G13 -> 0 | U13: =1/9*H13 -> 0.11111111 | V13: =1/9*I13 -> 0 | W13: =1/9*J13 -> 0 | ... Y13: =1/9*L13 -> 1 | AA13: {=+SUM($P$3:$Y$3*P13:Y13)} -> 0.50617284 | AB13: =+AA13/COUNTIF(P13:Y13,">0") -> 0.25308642 | AC13: 10
AA15: Composite SRL | AC15: =SUM(AB4:AB13)/COUNT(AC4:AC13) -> 0.22226337
A16: SRL transition model TRL and IRL = 1 | N16: SRL transition model
A17: Component Ids | C17: 1 | D17: 2 | E17: 3 | F17: 4 | G17: 5 | H17: 6 | I17: 7 | J17: 8 | K17: 9 | L17: 10 | N17: Component Ids | P17: 1 | Q17: 2 | R17: 3 | S17: 4 | T17: 5 | U17: 6 | V17: 7 | W17: 8 | X17: 9 | Y17: 10
B18: TRL | C18: 1 | D18: =C18 -> 1 | E18: =D18 -> 1 | F18: =E18 -> 1 | G18: =F18 -> 1 | H18: =G18 -> 1 | I18: =H18 -> 1 | J18: =I18 -> 1 | K18: =J18 -> 1 | L18: =K18 -> 1 | O18: TRL | P18: =1/9*C18 -> 0.11111111 | Q18: =1/9*D18 -> 0.11111111 | R18: =1/9*E18 -> 0.11111111 | S18: =1/9*F18 -> 0.11111111 | T18: =1/9*G18 -> 0.11111111 | U18: =1/9*H18 -> 0.11111111 | V18: =1/9*I18 -> 0.11111111 | W18: =1/9*J18 -> 0.11111111 | ... Y18: =1/9*L18 -> 0.11111111 | AB18: Composite SRL
A19: IRL | B19: 1 | C19: 1 | D19: =C19 -> 1 | E19: =D19 -> 1 | F19: =E19 -> 1 | G19: =F19 -> 1 | H19: =G19 -> 1 | I19: =H19 -> 1 | J19: =I19 -> 1 | K19: =J19 -> 1 | L19: =K19 -> 1 | N19: IRL | O19: 1 | P19: =1/9*C19 -> 0.11111111 | Q19: =1/9*D19 -> 0.11111111 | R19: =1/9*E19 -> 0.11111111 | S19: =1/9*F19 -> 0.11111111 | T19: =1/9*G19 -> 0.11111111 | U19: =1/9*H19 -> 0.11111111 | V19: =1/9*I19 -> 0.11111111 | W19: =1/9*J19 -> 0.11111111 | ... Y19: =1/9*L19 -> 0.11111111 | AA19: {=+SUM($P$18:$Y$18*P19:Y19)} -> 0.12345679 | AB19: =+AA19/COUNTIF(P19:Y19,">0") -> 0.012345679
P20: =+P18*P19 -> 0.012345679
A22: SRL transition model TRL and IRL = 2 | N22: SRL transition model
A23: Component Ids | C23: 1 | D23: 2 | E23: 3 | F23: 4 | G23: 5 | H23: 6 | I23: 7 | J23: 8 | K23: 9 | L23: 10 | N23: Component Ids | P23: 1 | Q23: 2 | R23: 3 | S23: 4 | T23: 5 | U23: 6 | V23: 7 | W23: 8 | X23: 9 | Y23: 10
B24: TRL | C24: 2 | D24: =C24 -> 2 | E24: =D24 -> 2 | F24: =E24 -> 2 | G24: =F24 -> 2 | H24: =G24 -> 2 | I24: =H24 -> 2 | J24: =I24 -> 2 | K24: =J24 -> 2 | L24: =K24 -> 2 | O24: TRL | P24: =1/9*C24 -> 0.22222222 | Q24: =1/9*D24 -> 0.22222222 | R24: =1/9*E24 -> 0.22222222 | S24: =1/9*F24 -> 0.22222222 | T24: =1/9*G24 -> 0.22222222 | U24: =1/9*H24 -> 0.22222222 | V24: =1/9*I24 -> 0.22222222 | W24: =1/9*J24 -> 0.22222222 | ... Y24: =1/9*L24 -> 0.22222222 | AB24: Composite SRL
A25: IRL | B25: 1 | C25: 2 | D25: =C25 -> 2 | E25: =D25 -> 2 | F25: =E25 -> 2 | G25: =F25 -> 2 | H25: =G25 -> 2 | I25: =H25 -> 2 | J25: =I25 -> 2 | K25: =J25 -> 2 | L25: =K25 -> 2 | N25: IRL | O25: 1 | P25: =1/9*C25 -> 0.22222222 | Q25: =1/9*D25 -> 0.22222222 | R25: =1/9*E25 -> 0.22222222 | S25: =1/9*F25 -> 0.22222222 | T25: =1/9*G25 -> 0.22222222 | U25: =1/9*H25 -> 0.22222222 | V25: =1/9*I25 -> 0.22222222 | W25: =1/9*J25 -> 0.22222222 | ... Y25: =1/9*L25 -> 0.22222222 | AA25: {=+SUM(P24:Y24*P25:Y25)} -> 0.49382716 | AB25: =+AA25/COUNTIF(P25:Y25,">0") -> 0.049382716
P26: =+P24*P25 -> 0.049382716
A28: SRL transition model TRL and IRL = 3 | N28: SRL transition model
A29: Component Ids | C29: 1 | D29: 2 | E29: 3 | F29: 4 | G29: 5 | H29: 6 | I29: 7 | J29: 8 | K29: 9 | L29: 10 | N29: Component Ids | P29: 1 | Q29: 2 | R29: 3 | S29: 4 | T29: 5 | U29: 6 | V29: 7 | W29: 8 | X29: 9 | Y29: 10
B30: TRL | C30: 3 | D30: =C30 -> 3 | E30: =D30 -> 3 | F30: =E30 -> 3 | G30: =F30 -> 3 | H30: =G30 -> 3 | I30: =H30 -> 3 | J30: =I30 -> 3 | K30: =J30 -> 3 | L30: =K30 -> 3 | O30: TRL | P30: =1/9*C30 -> 0.33333333 | Q30: =1/9*D30 -> 0.33333333 | R30: =1/9*E30 -> 0.33333333 | S30: =1/9*F30 -> 0.33333333 | T30: =1/9*G30 -> 0.33333333 | U30: =1/9*H30 -> 0.33333333 | V30: =1/9*I30 -> 0.33333333 | W30: =1/9*J30 -> 0.33333333 | ... Y30: =1/9*L30 -> 0.33333333 | AB30: Composite SRL
A31: IRL | B31: 1 | C31: 3 | D31: =C31 -> 3 | E31: =D31 -> 3 | F31: =E31 -> 3 | G31: =F31 -> 3 | H31: =G31 -> 3 | I31: =H31 -> 3 | J31: =I31 -> 3 | K31: =J31 -> 3 | L31: =K31 -> 3 | N31: IRL | O31: 1 | P31: =1/9*C31 -> 0.33333333 | Q31: =1/9*D31 -> 0.33333333 | R31: =1/9*E31 -> 0.33333333 | S31: =1/9*F31 -> 0.33333333 | T31: =1/9*G31 -> 0.33333333 | U31: =1/9*H31 -> 0.33333333 | V31: =1/9*I31 -> 0.33333333 | W31: =1/9*J31 -> 0.33333333 | ... Y31: =1/9*L31 -> 0.33333333 | AA31: {=+SUM(P30:Y30*P31:Y31)} -> 1.1111111 | AB31: =+AA31/COUNTIF(P31:Y31,">0") -> 0.11111111
A34: SRL transition model TRL and IRL = 4 | N34: SRL transition model
A35: Component Ids | C35: 1 | D35: 2 | E35: 3 | F35: 4 | G35: 5 | H35: 6 | I35: 7 | J35: 8 | K35: 9 | L35: 10 | N35: Component Ids | P35: 1 | Q35: 2 | R35: 3 | S35: 4 | T35: 5 | U35: 6 | V35: 7 | W35: 8 | X35: 9 | Y35: 10
B36: TRL | C36: 4 | D36: =C36 -> 4 | E36: =D36 -> 4 | F36: =E36 -> 4 | G36: =F36 -> 4 | H36: =G36 -> 4 | I36: =H36 -> 4 | J36: =I36 -> 4 | K36: =J36 -> 4 | L36: =K36 -> 4 | O36: TRL | P36: =1/9*C36 -> 0.44444444 | Q36: =1/9*D36 -> 0.44444444 | R36: =1/9*E36 -> 0.44444444 | S36: =1/9*F36 -> 0.44444444 | T36: =1/9*G36 -> 0.44444444 | U36: =1/9*H36 -> 0.44444444 | V36: =1/9*I36 -> 0.44444444 | W36: =1/9*J36 -> 0.44444444 | ... Y36: =1/9*L36 -> 0.44444444 | AB36: Composite SRL
A37: IRL | B37: 1 | C37: 4 | D37: =C37 -> 4 | E37: =D37 -> 4 | F37: =E37 -> 4 | G37: =F37 -> 4 | H37: =G37 -> 4 | I37: =H37 -> 4 | J37: =I37 -> 4 | K37: =J37 -> 4 | L37: =K37 -> 4 | N37: IRL | O37: 1 | P37: =1/9*C37 -> 0.44444444 | Q37: =1/9*D37 -> 0.44444444 | R37: =1/9*E37 -> 0.44444444 | S37: =1/9*F37 -> 0.44444444 | T37: =1/9*G37 -> 0.44444444 | U37: =1/9*H37 -> 0.44444444 | V37: =1/9*I37 -> 0.44444444 | W37: =1/9*J37 -> 0.44444444 | ... Y37: =1/9*L37 -> 0.44444444 | AA37: {=+SUM(P36:Y36*P37:Y37)} -> 1.9753086 | AB37: =+AA37/COUNTIF(P37:Y37,">0") -> 0.19753086
A40: SRL transition model TRL and IRL = 5 | N40: SRL transition model
A41: Component Ids | C41: 1 | D41: 2 | E41: 3 | F41: 4 | G41: 5 | H41: 6 | I41: 7 | J41: 8 | K41: 9 | L41: 10 | N41: Component Ids | P41: 1 | Q41: 2 | R41: 3 | S41: 4 | T41: 5 | U41: 6 | V41: 7 | W41: 8 | X41: 9 | Y41: 10
B42: TRL | C42: 5 | D42: =C42 -> 5 | E42: =D42 -> 5 | F42: =E42 -> 5 | G42: =F42 -> 5 | H42: =G42 -> 5 | I42: =H42 -> 5 | J42: =I42 -> 5 | K42: =J42 -> 5 | L42: =K42 -> 5 | O42: TRL | P42: =1/9*C42 -> 0.55555556 | Q42: =1/9*D42 -> 0.55555556 | R42: =1/9*E42 -> 0.55555556 | S42: =1/9*F42 -> 0.55555556 | T42: =1/9*G42 -> 0.55555556 | U42: =1/9*H42 -> 0.55555556 | V42: =1/9*I42 -> 0.55555556 | W42: =1/9*J42 -> 0.55555556 | ... Y42: =1/9*L42 -> 0.55555556 | AB42: Composite SRL
A43: IRL | B43: 1 | C43: 5 | D43: =C43 -> 5 | E43: =D43 -> 5 | F43: =E43 -> 5 | G43: =F43 -> 5 | H43: =G43 -> 5 | I43: =H43 -> 5 | J43: =I43 -> 5 | K43: =J43 -> 5 | L43: =K43 -> 5 | N43: IRL | O43: 1 | P43: =1/9*C43 -> 0.55555556 | Q43: =1/9*D43 -> 0.55555556 | R43: =1/9*E43 -> 0.55555556 | S43: =1/9*F43 -> 0.55555556 | T43: =1/9*G43 -> 0.55555556 | U43: =1/9*H43 -> 0.55555556 | V43: =1/9*I43 -> 0.55555556 | W43: =1/9*J43 -> 0.55555556 | ... Y43: =1/9*L43 -> 0.55555556 | AA43: {=+SUM(P42:Y42*P43:Y43)} -> 3.0864198 | AB43: =+AA43/COUNTIF(P43:Y43,">0") -> 0.30864198
A46: SRL transition model TRL and IRL = 6 | N46: SRL transition model
A47: Component Ids | C47: 1 | D47: 2 | E47: 3 | F47: 4 | G47: 5 | H47: 6 | I47: 7 | J47: 8 | K47: 9 | L47: 10 | N47: Component Ids | P47: 1 | Q47: 2 | R47: 3 | S47: 4 | T47: 5 | U47: 6 | V47: 7 | W47: 8 | X47: 9 | Y47: 10
B48: TRL | C48: 6 | D48: =C48 -> 6 | E48: =D48 -> 6 | F48: =E48 -> 6 | G48: =F48 -> 6 | H48: =G48 -> 6 | I48: =H48 -> 6 | J48: =I48 -> 6 | K48: =J48 -> 6 | L48: =K48 -> 6 | O48: TRL | P48: =1/9*C48 -> 0.66666667 | Q48: =1/9*D48 -> 0.66666667 | R48: =1/9*E48 -> 0.66666667 | S48: =1/9*F48 -> 0.66666667 | T48: =1/9*G48 -> 0.66666667 | U48: =1/9*H48 -> 0.66666667 | V48: =1/9*I48 -> 0.66666667 | W48: =1/9*J48 -> 0.66666667 | ... Y48: =1/9*L48 -> 0.66666667 | AB48: Composite SRL
A49: IRL | B49: 1 | C49: 6 | D49: =C49 -> 6 | E49: =D49 -> 6 | F49: =E49 -> 6 | G49: =F49 -> 6 | H49: =G49 -> 6 | I49: =H49 -> 6 | J49: =I49 -> 6 | K49: =J49 -> 6 | L49: =K49 -> 6 | N49: IRL | O49: 1 | P49: =1/9*C49 -> 0.66666667 | Q49: =1/9*D49 -> 0.66666667 | R49: =1/9*E49 -> 0.66666667 | S49: =1/9*F49 -> 0.66666667 | T49: =1/9*G49 -> 0.66666667 | U49: =1/9*H49 -> 0.66666667 | V49: =1/9*I49 -> 0.66666667 | W49: =1/9*J49 -> 0.66666667 | ... Y49: =1/9*L49 -> 0.66666667 | AA49: {=+SUM(P48:Y48*P49:Y49)} -> 4.4444444 | AB49: =+AA49/COUNTIF(P49:Y49,">0") -> 0.44444444
...

Sheet SRL Transition Model
N2: Component Ids | O2: 1 | P2: 2 | Q2: 3 | R2: 4 | S2: 5 | T2: 6 | U2: 7 | V2: 8 | W2: 9 | X2: 10
B3: TRL | C3: IRL | D3: Composite SRL | E3: Midtpoint levels | F3: Composite SRL Range | G3: SRL | I3: SRA Calculated | J3: SRA measured | N3: Component SRL | O3: ='SRL beregninger'!AB4 -> 0.24691358 | P3: ='SRL beregninger'!AB5 -> 0.24074074 | Q3: ='SRL beregninger'!AB6 -> 0.2962963 | R3: ='SRL beregninger'!AB7 -> 0.30041152 | S3: ='SRL beregninger'!AB8 -> 0.2345679 | T3: ='SRL beregninger'!AB9 -> 0.16296296 | U3: ='SRL beregninger'!AB10 -> 0.18518519 | V3: ='SRL beregninger'!AB11 -> 0.12654321 | W3: ='SRL beregninger'!AB12 -> 0.17592593 | X3: ='SRL beregninger'!AB13 -> 0.25308642
B4: 9 | C4: 9 | D4: ='SRL beregninger'!AB67 -> 1 | E4: =+(D4+D5)/2 -> 0.89506173 | F4: =TEXT(E4,"#.##0,000")&" - "&1 -> 0,895 - 1 | G4: 9 | I4: ='SRL beregninger'!AC15 -> 0.22226337 | J4: =+IF($I$4>=E4,G4,"") | N4: Component SRA | O4: =+IF(O$3>=$E4,$G4,"") | P4: =+IF(P$3>=$E4,$G4,"") | Q4: =+IF(Q$3>=$E4,$G4,"") | R4: =+IF(R$3>=$E4,$G4,"") | S4: =+IF(S$3>=$E4,$G4,"") | T4: =+IF(T$3>=$E4,$G4,"") | U4: =+IF(U$3>=$E4,$G4,"") | V4: =+IF(V$3>=$E4,$G4,"") | ... X4: =+IF(X$3>=$E4,$G4,"")
B5: 8 | C5: 8 | D5: ='SRL beregninger'!AB61 -> 0.79012346 | E5: =+(D5+D6)/2 -> 0.69753086 | F5: =TEXT(E5,"#.##0,000")&" - "&(TEXT(E4,"#.###,000"))-0.001 -> 0,698 - 0,894 | G5: 8 | J5: =+IF($I$4>=E5,IF($I$4<=E4,G5,""),"") | O5: =+IF(O$3>=$E5,IF(O$3<$E4,$G5,""),"") | P5: =+IF(P$3>=$E5,IF(P$3<$E4,$G5,""),"") | Q5: =+IF(Q$3>=$E5,IF(Q$3<$E4,$G5,""),"") | R5: =+IF(R$3>=$E5,IF(R$3<$E4,$G5,""),"") | S5: =+IF(S$3>=$E5,IF(S$3<$E4,$G5,""),"") | T5: =+IF(T$3>=$E5,IF(T$3<$E4,$G5,""),"") | U5: =+IF(U$3>=$E5,IF(U$3<$E4,$G5,""),"") | V5: =+IF(V$3>=$E5,IF(V$3<$E4,$G5,""),"") | ... X5: =+IF(X$3>=$E5,IF(X$3<$E4,$G5,""),"")
B6: 7 | C6: 7 | D6: ='SRL beregninger'!AB55 -> 0.60493827 | E6: =+(D6+D7)/2 -> 0.52469136 | F6: =TEXT(E6,"#.##0,000")&" - "&(TEXT(E5,"#.###,000"))-0.001 -> 0,525 - 0,697 | G6: 7 | J6: =+IF($I$4>=E6,IF($I$4<=E5,G6,""),"") | O6: =+IF(O$3>=$E6,IF(O$3<$E5,$G6,""),"") | P6: =+IF(P$3>=$E6,IF(P$3<$E5,$G6,""),"") | Q6: =+IF(Q$3>=$E6,IF(Q$3<$E5,$G6,""),"") | R6: =+IF(R$3>=$E6,IF(R$3<$E5,$G6,""),"") | S6: =+IF(S$3>=$E6,IF(S$3<$E5,$G6,""),"") | T6: =+IF(T$3>=$E6,IF(T$3<$E5,$G6,""),"") | U6: =+IF(U$3>=$E6,IF(U$3<$E5,$G6,""),"") | V6: =+IF(V$3>=$E6,IF(V$3<$E5,$G6,""),"") | ... X6: =+IF(X$3>=$E6,IF(X$3<$E5,$G6,""),"")
B7: 6 | C7: 6 | D7: ='SRL beregninger'!AB49 -> 0.44444444 | E7: =+(D7+D8)/2 -> 0.37654321 | F7: =TEXT(E7,"#.##0,000")&" - "&(TEXT(E6,"#.###,000"))-0.001 -> 0,377 - 0,524 | G7: 6 | J7: =+IF($I$4>=E7,IF($I$4<=E6,G7,""),"") | O7: =+IF(O$3>=$E7,IF(O$3<$E6,$G7,""),"") | P7: =+IF(P$3>=$E7,IF(P$3<$E6,$G7,""),"") | Q7: =+IF(Q$3>=$E7,IF(Q$3<$E6,$G7,""),"") | R7: =+IF(R$3>=$E7,IF(R$3<$E6,$G7,""),"") | S7: =+IF(S$3>=$E7,IF(S$3<$E6,$G7,""),"") | T7: =+IF(T$3>=$E7,IF(T$3<$E6,$G7,""),"") | U7: =+IF(U$3>=$E7,IF(U$3<$E6,$G7,""),"") | V7: =+IF(V$3>=$E7,IF(V$3<$E6,$G7,""),"") | ... X7: =+IF(X$3>=$E7,IF(X$3<$E6,$G7,""),"")
B8: 5 | C8: 5 | D8: ='SRL beregninger'!AB43 -> 0.30864198 | E8: =+(D8+D9)/2 -> 0.25308642 | F8: =+TEXT(E8,"#.##0,000")&" - "&(TEXT(E7,"#.###,000"))-0.001 -> 0,253 - 0,376 | G8: 5 | J8: =+IF($I$4>=E8,IF($I$4<=E7,G8,""),"") | O8: =+IF(O$3>=$E8,IF(O$3<$E7,$G8,""),"") | P8: =+IF(P$3>=$E8,IF(P$3<$E7,$G8,""),"") | Q8: =+IF(Q$3>=$E8,IF(Q$3<$E7,$G8,""),"") -> 5 | R8: =+IF(R$3>=$E8,IF(R$3<$E7,$G8,""),"") -> 5 | S8: =+IF(S$3>=$E8,IF(S$3<$E7,$G8,""),"") | T8: =+IF(T$3>=$E8,IF(T$3<$E7,$G8,""),"") | U8: =+IF(U$3>=$E8,IF(U$3<$E7,$G8,""),"") | V8: =+IF(V$3>=$E8,IF(V$3<$E7,$G8,""),"") | ... X8: =+IF(X$3>=$E8,IF(X$3<$E7,$G8,""),"") -> 5
B9: 4 | C9: 4 | D9: ='SRL beregninger'!AB37 -> 0.19753086 | E9: =+(D9+D10)/2 -> 0.15432099 | F9: =TEXT(E9,"#.##0,000")&" - "&(TEXT(E8,"#.###,000"))-0.001 -> 0,154 - 0,252 | G9: 4 | J9: =+IF($I$4>=E9,IF($I$4<=E8,G9,""),"") -> 4 | O9: =+IF(O$3>=$E9,IF(O$3<$E8,$G9,""),"") -> 4 | P9: =+IF(P$3>=$E9,IF(P$3<$E8,$G9,""),"") -> 4 | Q9: =+IF(Q$3>=$E9,IF(Q$3<$E8,$G9,""),"") | R9: =+IF(R$3>=$E9,IF(R$3<$E8,$G9,""),"") | S9: =+IF(S$3>=$E9,IF(S$3<$E8,$G9,""),"") -> 4 | T9: =+IF(T$3>=$E9,IF(T$3<$E8,$G9,""),"") -> 4 | U9: =+IF(U$3>=$E9,IF(U$3<$E8,$G9,""),"") -> 4 | V9: =+IF(V$3>=$E9,IF(V$3<$E8,$G9,""),"") | ... X9: =+IF(X$3>=$E9,IF(X$3<$E8,$G9,""),"")
B10: 3 | C10: 3 | D10: ='SRL beregninger'!AB31 -> 0.11111111 | E10: =+(D10+D11)/2 -> 0.080246914 | F10: =TEXT(E10,"#.##0,000")&" - "&(TEXT(E9,"#.###,000"))-0.001 -> 0,080 - 0,153 | G10: 3 | J10: =+IF($I$4>=E10,IF($I$4<=E9,G10,""),"") | O10: =+IF(O$3>=$E10,IF(O$3<$E9,$G10,""),"") | P10: =+IF(P$3>=$E10,IF(P$3<$E9,$G10,""),"") | Q10: =+IF(Q$3>=$E10,IF(Q$3<$E9,$G10,""),"") | R10: =+IF(R$3>=$E10,IF(R$3<$E9,$G10,""),"") | S10: =+IF(S$3>=$E10,IF(S$3<$E9,$G10,""),"") | T10: =+IF(T$3>=$E10,IF(T$3<$E9,$G10,""),"") | U10: =+IF(U$3>=$E10,IF(U$3<$E9,$G10,""),"") | V10: =+IF(V$3>=$E10,IF(V$3<$E9,$G10,""),"") -> 3 | ... X10: =+IF(X$3>=$E10,IF(X$3<$E9,$G10,""),"")
B11: 2 | C11: 2 | D11: ='SRL beregninger'!AB25 -> 0.049382716 | E11: =+(D11+D12)/2 -> 0.030864198 | F11: =+TEXT(E11,"#.##0,000")&" - "&(TEXT(E10,"#.###,000"))-0.001 -> 0,031 - 0,079 | G11: 2 | J11: =+IF($I$4>=E11,IF($I$4<=E10,G11,""),"") | O11: =+IF(O$3>=$E11,IF(O$3<$E10,$G11,""),"") | P11: =+IF(P$3>=$E11,IF(P$3<$E10,$G11,""),"") | Q11: =+IF(Q$3>=$E11,IF(Q$3<$E10,$G11,""),"") | R11: =+IF(R$3>=$E11,IF(R$3<$E10,$G11,""),"") | S11: =+IF(S$3>=$E11,IF(S$3<$E10,$G11,""),"") | T11: =+IF(T$3>=$E11,IF(T$3<$E10,$G11,""),"") | U11: =+IF(U$3>=$E11,IF(U$3<$E10,$G11,""),"") | V11: =+IF(V$3>=$E11,IF(V$3<$E10,$G11,""),"") | ... X11: =+IF(X$3>=$E11,IF(X$3<$E10,$G11,""),"")
B12: 1 | C12: 1 | D12: ='SRL beregninger'!AB19 -> 0.012345679 | E12: 0 | F12: =+"0,000 - "&(TEXT(E11,"#.###,000"))-0.001 -> 0,000 - 0,03 | G12: 1 | J12: =+IF($I$4>=E12,IF($I$4<=E11,G12,""),"") | O12: =+IF(O$3>=$E12,IF(O$3<$E11,$G12,""),"") | P12: =+IF(P$3>=$E12,IF(P$3<$E11,$G12,""),"") | Q12: =+IF(Q$3>=$E12,IF(Q$3<$E11,$G12,""),"") | R12: =+IF(R$3>=$E12,IF(R$3<$E11,$G12,""),"") | S12: =+IF(S$3>=$E12,IF(S$3<$E11,$G12,""),"") | T12: =+IF(T$3>=$E12,IF(T$3<$E11,$G12,""),"") | U12: =+IF(U$3>=$E12,IF(U$3<$E11,$G12,""),"") | V12: =+IF(V$3>=$E12,IF(V$3<$E11,$G12,""),"") | ... X12: =+IF(X$3>=$E12,IF(X$3<$E11,$G12,""),"")
O15: =_xlfn.XLOOKUP(O3,$E$4:$E$12,$G$4:$G$12,,-1) -> 4 | P15: =_xlfn.XLOOKUP(P3,$E$4:$E$12,$G$4:$G$12,,-1) -> 4 | Q15: =_xlfn.XLOOKUP(Q3,$E$4:$E$12,$G$4:$G$12,,-1) -> 5 | R15: =_xlfn.XLOOKUP(R3,$E$4:$E$12,$G$4:$G$12,,-1) -> 5 | S15: =_xlfn.XLOOKUP(S3,$E$4:$E$12,$G$4:$G$12,,-1) -> 4 | T15: =_xlfn.XLOOKUP(T3,$E$4:$E$12,$G$4:$G$12,,-1) -> 4 | U15: =_xlfn.XLOOKUP(U3,$E$4:$E$12,$G$4:$G$12,,-1) -> 4 | V15: =_xlfn.XLOOKUP(V3,$E$4:$E$12,$G$4:$G$12,,-1) -> 3 | ... X15: =_xlfn.XLOOKUP(X3,$E$4:$E$12,$G$4:$G$12,,-1) -> 5

Sheet Test data
A1: Output system | B1: TRL-F | C1: From system name | D1: From SO | E1: From Org | F1: IRL → | G1: I-Class → | H1: I-Class ← | I1: IRL ← | J1: Input system | K1: TRL-To | L1: To system name | M1: To SO | N1: To Org
A2: =1.1.1 | B2: 5 | C2: MV Switchgear System, WTG | D2: HATHO | E2: WTG | F2: 3 | G2: E_, FC | H2: E_, FC | I2: 3 | J2: =3.1.2 | K2: 7 | L2: ICC/PCC cable system (66kV) | M2: XSTPH | N2: ELS
A3: =1.1.1 | B3: 5 | C3: MV Switchgear System, WTG | D3: HATHO | E3: WTG | F3: 3 | G3: B_ | J3: =4.4.1 | K3: 6 | L3: Substation Control system (SCS) | M3: MICHN | N3: ELS
A4: =1.1.1 | B4: 5 | C4: MV Switchgear System, WTG | D4: HATHO | E4: WTG | F4: 4 | G4: EB, EC | J4: =2.1.1 | K4: 5 | L4: MV Cable Routing System | M4: KIMLJ | N4: WTG
A5: =1.1.1 | B5: 5 | C5: MV Switchgear System, WTG | D5: HATHO | E5: WTG | F5: 3 | G5: BC | J5: =1.5.1 | K5: 6 | L5: Disturbance measurement system | M5: IBFAL | N5: ELS
A6: =1.1.1 | B6: 5 | C6: MV Switchgear System, WTG | D6: HATHO | E6: WTG | F6: 3 | G6: AA | J6: =1.5.1 | K6: 6 | L6: Disturbance measurement system | M6: IBFAL | N6: ELS
A7: =1.1.1 | B7: 5 | C7: MV Switchgear System, WTG | D7: HATHO | E7: WTG | F7: 3 | G7: B_ | J7: =4.4.2 | K7: 6 | L7: Park Server System (WTG SCADA) | M7: IBFAL | N7: ELS
A8: =1.1.1 | B8: 5 | C8: MV Switchgear System, WTG | D8: HATHO | E8: WTG | F8: 4 | G8: B_ | J8: =10.4.2 | K8: 6 | L8: Park Server System (WTG SCADA) | M8: IBFAL | N8: ELS
A9: =1.1.1 | B9: 5 | C9: MV Switchgear System, WTG | D9: HATHO | E9: WTG | F9: 4 | G9: BB | J9: =1.4.3 | K9: 6 | L9: Protection system wind turbine generator (WTG) | M9: HATHO | N9: WTG
A10: =10.7.5 | B10: 6 | C10: Telecom Management System | D10: COLHO | E10: ELS | F10: 3 | G10: BA | H10: BA | I10: 3 | J10: =10.7.2 | K10: 6 | L10: 4G Telecom System | M10: XNEER | N10: ELS
A11: =10.7.6 | B11: 6 | C11: Network Backbone System | D11: COLHO | E11: ELS | F11: 3 | G11: FB | H11: FB | I11: 3 | J11: =10.7.2 | K11: 6 | L11: 4G Telecom System | M11: XNEER | N11: ELS
A12: =10.7.6 | B12: 6 | C12: Network Backbone System | D12: COLHO | E12: ELS | F12: 4 | G12: A_ | H12: A_ | I12: 4 | J12: =5.7.12 | K12: 5 | L12: Network Backbone System | M12: COLHO | N12: ELS
A13: =11.4.2 | B13: 6 | C13: Fiber distribution system (YCC) | D13: COLHO | E13: ELS | F13: 3 | G13: FC | J13: =10.7.7 | K13: 6 | L13: Fiber distribution system (YCC) | M13: COLHO | N13: ELS
A14: =12.3.1 | B14: 6 | C14: 4G Telecom System | D14: ERIHO | E14: ELS | F14: 4 | G14: FA | J14: =1.4.4 | K14: 6 | L14: 4G Telecom System | M14: XNEER | N14: ELS
A15: =12.3.1 | B15: 6 | C15: 4G Telecom System | D15: ERIHO | E15: ELS | F15: 4 | G15: FA | J15: =4.10.3 | K15: 6 | L15: 4G Telecom System | M15: XNEER | N15: ELS
A16: =12.3.1 | B16: 6 | C16: 4G Telecom System | D16: ERIHO | E16: ELS | F16: 4 | G16: FA | H16: FA | I16: 4 | J16: =5.7.3 | K16: 5 | L16: 4G Telecom System | M16: XNEER | N16: ELS
A17: =12.3.1 | B17: 6 | C17: 4G Telecom System | D17: ERIHO | E17: ELS | F17: 4 | G17: FA | H17: FA | I17: 4 | J17: =10.7.2 | K17: 6 | L17: 4G Telecom System | M17: XNEER | N17: ELS
A18: =2.1.1 | B18: 5 | C18: MV Cable Routing System | D18: KIMLJ | E18: WTG | F18: 3 | G18: E_, EC, EB, EA | J18: =3.1.2 | K18: 7 | L18: ICC/PCC cable system (66kV) | M18: XSTPH | N18: ELS
A19: =2.1.1 | B19: 5 | C19: MV Cable Routing System | D19: KIMLJ | E19: WTG | F19: 4 | G19: EA | J19: =1.1.1 | K19: 5 | L19: MV Switchgear System, WTG | M19: HATHO | N19: WTG
A20: =2.1.1 | B20: 5 | C20: MV Cable Routing System | D20: KIMLJ | E20: WTG | F20: 3 | G20: EA | J20: =2.2.1 | K20: 5 | L20: TETRA External Antenna System | M20: COLHO | N20: ELS
A21: =3.1.2 | B21: 7 | C21: ICC/PCC cable system (66kV) | D21: XSTPH | E21: ELS | F21: 3 | G21: FB | J21: =1.1.1 | K21: 5 | L21: MV Switchgear System, WTG | M21: HATHO | N21: WTG
A22: =4.1.2 | B22: 8 | C22: MV GIS system | D22: XMMCS | E22: ELS | F22: 4 | G22: CA, CB, FA, FC, E_ | J22: =3.1.2 | K22: 7 | L22: ICC/PCC cable system (66kV) | M22: XSTPH | N22: ELS
A23: =4.1.3 | B23: 7 | C23: Main transformer system | D23: XBOLA | E23: ELS | F23: 4 | G23: CA, CB | J23: =3.1.2 | K23: 7 | L23: ICC/PCC cable system (66kV) | M23: XSTPH | N23: ELS
A24: =4.1.5 | B24: 8 | C24: Earthing Auxiliary Transformer (EAT) System | D24: XBARH | E24: ELS | F24: 3 | G24: CA, CB | H24: CA, CB | I24: 3 | J24: =3.1.2 | K24: 7 | L24: ICC/PCC cable system (66kV) | M24: XSTPH | N24: ELS
A25: =4.1.6 | B25: 7 | C25: Neutral Earthing Resistor (NER) System | D25: XBARH | E25: ELS | F25: 3 | G25: CA, CB | H25: CA, CB | I25: 3 | J25: =3.1.2 | K25: 7 | L25: ICC/PCC cable system (66kV) | M25: XSTPH | N25: ELS
A26: =4.1.8 | B26: 6 | C26: MV cable connecting system | D26: SIMCO | E26: ELS | F26: 3 | G26: EA | H26: E_ | I26: 3 | J26: =3.1.2 | K26: 7 | L26: ICC/PCC cable system (66kV) | M26: XSTPH | N26: ELS
A27: =4.10.10 | B27: 6 | C27: Telecom Management System | D27: COLHO | E27: ELS | F27: 3 | G27: BA | H27: BA | I27: 3 | J27: =4.10.3 | K27: 6 | L27: 4G Telecom System | M27: XNEER | N27: ELS
A28: =4.10.12 | B28: 6 | C28: Network Backbone System | D28: COLHO | E28: ELS | F28: 4 | G28: AA, FA | H28: FB | I28: 3 | J28: =4.10.3 | K28: 6 | L28: 4G Telecom System | M28: XNEER | N28: ELS
A29: =4.10.12 | B29: 6 | C29: Network Backbone System | D29: COLHO | E29: ELS | F29: 4 | G29: A_ | J29: =10.7.6 | K29: 6 | L29: Network Backbone System | M29: COLHO | N29: ELS
A30: =4.10.13 | B30: 6 | C30: Fiber distribution system (YCC) | D30: COLHO | E30: ELS | F30: 4 | G30: FB | H30: FB, B_, FC | I30: 3 | J30: =3.1.2 | K30: 7 | L30: ICC/PCC cable system (66kV) | M30: XSTPH | N30: ELS
A31: =4.13.3 | B31: 5 | C31: J-TUBE System | D31: FELNM | E31: OSS | F31: 4 | G31: E_ | H31: E_ | I31: 4 | J31: =3.1.2 | K31: 7 | L31: ICC/PCC cable system (66kV) | M31: XSTPH | N31: ELS
A32: =4.2.1 | B32: 6 | C32: Uninterruptible Power Supply system (UPS) | D32: HOLSE | E32: OSS | F32: 4 | G32: CA | J32: =4.10.3 | K32: 6 | L32: 4G Telecom System | M32: XNEER | N32: ELS
A33: =4.2.2 | B33: 6 | C33: Low voltage main supply system (SWB) | D33: HOLSE | E33: OSS | F33: 4 | G33: CA | J33: =4.10.3 | K33: 6 | L33: 4G Telecom System | M33: XNEER | N33: ELS
A34: =4.2.6 | B34: 6 | C34: Earthing / grounding system | D34: HOLSE | E34: OSS | F34: 4 | G34: CB | H34: CB | I34: 4 | J34: =3.1.2 | K34: 7 | L34: ICC/PCC cable system (66kV) | M34: XSTPH | N34: ELS
A35: =4.2.6 | B35: 6 | C35: Earthing / grounding system | D35: HOLSE | E35: OSS | F35: 3 | G35: CB | H35: CB | I35: 3 | J35: =4.10.3 | K35: 6 | L35: 4G Telecom System | M35: XNEER | N35: ELS
A36: =4.6.2 | B36: 6 | C36: Cooling/Heating System | D36: POREI | E36: OSS | F36: 4 | G36: CD | H36: CC | I36: 3 | J36: =4.10.3 | K36: 6 | L36: 4G Telecom System | M36: XNEER | N36: ELS
A37: =4.7.4 | B37: 6 | C37: Electrical cable pulling winch | D37: POREI | E37: OSS | F37: 2 | G37: EA | J37: =4.7.9 | K37: 6 | L37: Equipment spacing system (3D) | M37: POREI | N37: OSS
A38: =4.7.4 | B38: 6 | C38: Electrical cable pulling winch | D38: POREI | E38: OSS | F38: 2 | G38: FC | J38: =4.7.9 | K38: 6 | L38: Equipment spacing system (3D) | M38: POREI | N38: OSS
A39: =4.7.5 | B39: 6 | C39: High/Medium voltage cable tray system | D39: HOLSE | E39: OSS | F39: 3 | G39: E_ | H39: E_ | I39: 3 | J39: =3.1.2 | K39: 7 | L39: ICC/PCC cable system (66kV) | M39: XSTPH | N39: ELS
A40: =4.7.6 | B40: 6 | C40: Low voltage cable tray system | D40: HOLSE | E40: OSS | F40: 3 | G40: EB, EC | H40: EB, EC | I40: 3 | J40: =3.1.2 | K40: 7 | L40: ICC/PCC cable system (66kV) | M40: XSTPH | N40: ELS
...

Sheet SRL Test
A2: Systems ID | C2: 1.1.1 | D2: 2.1.1 | E2: 3.1.2 | F2: 4.1.2 | G2: 4.1.3 | H2: 4.1.5 | I2: 4.1.6 | J2: 4.1.8 | K2: 4.2.1 | L2: 4.2.2 | M2: 4.2.6 | N2: 4.6.2 | O2: 4.7.4 | P2: 4.7.5 | Q2: 4.7.6 | R2: 4.7.9 | S2: 4.10.10 | T2: 4.10.12 | U2: 4.10.13 | V2: 4.13.3 | W2: 5.2.1 | X2: 5.2.2 | Y2: 5.2.6 | Z2: 5.6.2 | AA2: 5.7.3 | AB2: 5.7.12 | AC2: 5.7.13 | AD2: 5.11.4 | AE2: 10.7.5 | AF2: 10.7.6 | AG2: 11.4.2 | AH2: 12.3.1
B3: TRL | C3: 5 | D3: 5 | E3: 7 | F3: 8 | G3: 7 | H3: 8 | I3: 7 | J3: 6 | K3: 6 | L3: 6 | M3: 6 | N3: 6 | O3: 6 | P3: 6 | Q3: 6 | R3: 6 | S3: 6 | T3: 6 | U3: 6 | V3: 5 | W3: 5 | X3: 5 | Y3: 5 | Z3: 5 | AA3: 5 | AB3: 5 | AC3: 5 | AD3: 5 | AE3: 6 | AF3: 6 | AG3: 6 | AH3: 6
A4: IRL | B4: 1.1.1 | C4: 9 | D4: 4 | E4: 3 | F4: 0 | G4: 0 | H4: 0 | I4: 0 | J4: 0 | K4: 0 | L4: 0 | M4: 0 | N4: 0 | O4: 0 | P4: 0 | Q4: 0 | R4: 0 | S4: 0 | T4: 0 | U4: 0 | V4: 0 | W4: 0 | X4: 0 | Y4: 0 | Z4: 0 | AA4: 0 | AB4: 0 | AC4: 0 | AD4: 0 | AE4: 0 | AF4: 0 | AG4: 0 | AH4: 0
B5: 2.1.1 | C5: 4 | D5: 9 | E5: 3 | F5: 0 | G5: 0 | H5: 0 | I5: 0 | J5: 0 | K5: 0 | L5: 0 | M5: 0 | N5: 0 | O5: 0 | P5: 0 | Q5: 0 | R5: 0 | S5: 0 | T5: 0 | U5: 0 | V5: 0 | W5: 0 | X5: 0 | Y5: 0 | Z5: 0 | AA5: 0 | AB5: 0 | AC5: 0 | AD5: 0 | AE5: 0 | AF5: 0 | AG5: 0 | AH5: 0
B6: 3.1.2 | C6: 3 | D6: 0 | E6: 9 | F6: 0 | G6: 0 | H6: 0 | I6: 0 | J6: 0 | K6: 0 | L6: 0 | M6: 0 | N6: 0 | O6: 0 | P6: 3 | Q6: 3 | R6: 3 | S6: 0 | T6: 0 | U6: 3 | V6: 4 | W6: 0 | X6: 0 | Y6: 0 | Z6: 0 | AA6: 0 | AB6: 0 | AC6: 0 | AD6: 0 | AE6: 0 | AF6: 0 | AG6: 0 | AH6: 0
B7: 4.1.2 | C7: 0 | D7: 0 | E7: 4 | F7: 9 | G7: 0 | H7: 0 | I7: 0 | J7: 0 | K7: 0 | L7: 0 | M7: 0 | N7: 0 | O7: 0 | P7: 0 | Q7: 0 | R7: 0 | S7: 0 | T7: 0 | U7: 0 | V7: 0 | W7: 0 | X7: 0 | Y7: 0 | Z7: 0 | AA7: 0 | AB7: 0 | AC7: 0 | AD7: 0 | AE7: 0 | AF7: 0 | AG7: 0 | AH7: 0
B8: 4.1.3 | C8: 0 | D8: 0 | E8: 4 | F8: 0 | G8: 9 | H8: 0 | I8: 0 | J8: 0 | K8: 0 | L8: 0 | M8: 0 | N8: 0 | O8: 0 | P8: 0 | Q8: 0 | R8: 0 | S8: 0 | T8: 0 | U8: 0 | V8: 0 | W8: 0 | X8: 0 | Y8: 0 | Z8: 0 | AA8: 0 | AB8: 0 | AC8: 0 | AD8: 0 | AE8: 0 | AF8: 0 | AG8: 0 | AH8: 0
B9: 4.1.5 | C9: 0 | D9: 0 | E9: 3 | F9: 0 | G9: 0 | H9: 9 | I9: 0 | J9: 0 | K9: 0 | L9: 0 | M9: 0 | N9: 0 | O9: 0 | P9: 0 | Q9: 0 | R9: 0 | S9: 0 | T9: 0 | U9: 0 | V9: 0 | W9: 0 | X9: 0 | Y9: 0 | Z9: 0 | AA9: 0 | AB9: 0 | AC9: 0 | AD9: 0 | AE9: 0 | AF9: 0 | AG9: 0 | AH9: 0
B10: 4.1.6 | C10: 0 | D10: 0 | E10: 3 | F10: 0 | G10: 0 | H10: 0 | I10: 9 | J10: 0 | K10: 0 | L10: 0 | M10: 0 | N10: 0 | O10: 0 | P10: 0 | Q10: 0 | R10: 0 | S10: 0 | T10: 0 | U10: 0 | V10: 0 | W10: 0 | X10: 0 | Y10: 0 | Z10: 0 | AA10: 0 | AB10: 0 | AC10: 0 | AD10: 0 | AE10: 0 | AF10: 0 | AG10: 0 | AH10: 0
B11: 4.1.8 | C11: 0 | D11: 0 | E11: 3 | F11: 0 | G11: 0 | H11: 0 | I11: 0 | J11: 9 | K11: 0 | L11: 0 | M11: 0 | N11: 0 | O11: 0 | P11: 0 | Q11: 0 | R11: 0 | S11: 0 | T11: 0 | U11: 0 | V11: 0 | W11: 0 | X11: 0 | Y11: 0 | Z11: 0 | AA11: 0 | AB11: 0 | AC11: 0 | AD11: 0 | AE11: 0 | AF11: 0 | AG11: 0 | AH11: 0
B12: 4.2.1 | C12: 0 | D12: 0 | E12: 0 | F12: 0 | G12: 0 | H12: 0 | I12: 0 | J12: 0 | K12: 9 | L12: 0 | M12: 0 | N12: 0 | O12: 0 | P12: 0 | Q12: 0 | R12: 0 | S12: 0 | T12: 0 | U12: 0 | V12: 0 | W12: 0 | X12: 0 | Y12: 0 | Z12: 0 | AA12: 0 | AB12: 0 | AC12: 0 | AD12: 0 | AE12: 0 | AF12: 0 | AG12: 0 | AH12: 0
B13: 4.2.2 | C13: 0 | D13: 0 | E13: 0 | F13: 0 | G13: 0 | H13: 0 | I13: 0 | J13: 0 | K13: 0 | L13: 9 | M13: 0 | N13: 0 | O13: 0 | P13: 0 | Q13: 0 | R13: 0 | S13: 0 | T13: 0 | U13: 0 | V13: 0 | W13: 0 | X13: 0 | Y13: 0 | Z13: 0 | AA13: 0 | AB13: 0 | AC13: 0 | AD13: 0 | AE13: 0 | AF13: 0 | AG13: 0 | AH13: 0
B14: 4.2.6 | C14: 0 | D14: 0 | E14: 3 | F14: 0 | G14: 0 | H14: 0 | I14: 0 | J14: 0 | K14: 0 | L14: 0 | M14: 9 | N14: 0 | O14: 0 | P14: 0 | Q14: 0 | R14: 0 | S14: 0 | T14: 0 | U14: 0 | V14: 0 | W14: 0 | X14: 0 | Y14: 0 | Z14: 0 | AA14: 0 | AB14: 0 | AC14: 0 | AD14: 0 | AE14: 0 | AF14: 0 | AG14: 0 | AH14: 0
B15: 4.6.2 | C15: 0 | D15: 0 | E15: 0 | F15: 0 | G15: 0 | H15: 0 | I15: 0 | J15: 0 | K15: 0 | L15: 0 | M15: 0 | N15: 9 | O15: 0 | P15: 0 | Q15: 0 | R15: 0 | S15: 0 | T15: 0 | U15: 0 | V15: 0 | W15: 0 | X15: 0 | Y15: 0 | Z15: 0 | AA15: 0 | AB15: 0 | AC15: 0 | AD15: 0 | AE15: 0 | AF15: 0 | AG15: 0 | AH15: 0
B16: 4.7.4 | C16: 0 | D16: 0 | E16: 0 | F16: 0 | G16: 0 | H16: 0 | I16: 0 | J16: 0 | K16: 0 | L16: 0 | M16: 0 | N16: 0 | O16: 9 | P16: 0 | Q16: 0 | R16: 2 | S16: 0 | T16: 0 | U16: 0 | V16: 0 | W16: 0 | X16: 0 | Y16: 0 | Z16: 0 | AA16: 0 | AB16: 0 | AC16: 0 | AD16: 0 | AE16: 0 | AF16: 0 | AG16: 0 | AH16: 0
... B35: 12.3.1 | C35: 0 | D35: 0 | E35: 0 | F35: 0 | G35: 0 | H35: 0 | I35: 0 | J35: 0 | K35: 0 | L35: 0 | M35: 0 | N35: 0 | O35: 0 | P35: 0 | Q35: 0 | R35: 0 | S35: 0 | T35: 0 | U35: 0 | V35: 0 | W35: 0 | X35: 0 | Y35: 0 | Z35: 0 | AA35: 0 | AB35: 4 | AC35: 0 | AD35: 0 | AE35: 0 | AF35: 0 | AG35: 0 | AH35: 9
AK37: SRA calc | AL37: SRA
A38: Systems ID | C38: 1.1.1 | D38: 2.1.1 | E38: 3.1.2 | F38: 4.1.2 | G38: 4.1.3 | H38: 4.1.5 | I38: 4.1.6 | J38: 4.1.8 | K38: 4.2.1 | L38: 4.2.2 | M38: 4.2.6 | N38: 4.6.2 | O38: 4.7.4 | P38: 4.7.5 | Q38: 4.7.6 | R38: 4.7.9 | S38: 4.10.10 | T38: 4.10.12 | U38: 4.10.13 | V38: 4.13.3 | W38: 5.2.1 | X38: 5.2.2 | Y38: 5.2.6 | Z38: 5.6.2 | AA38: 5.7.3 | AB38: 5.7.12 | AC38: 5.7.13 | AD38: 5.11.4 | AE38: 10.7.5 | AF38: 10.7.6 | AG38: 11.4.2 | AH38: 12.3.1 | AK38: =SUM(AK40:AK71)/COUNT(AK40:AK71) -> 0.48808605 | AL38: =+_xlfn.XLOOKUP('SRL Test'!AK38,'SRL Transition Model'!$E$4:$E$12,'SRL Transition Model'!$G$4:$G$12,,-1) -> 6
B39: TRL | C39: =1/9*C3 -> 0.55555556 | D39: =1/9*D3 -> 0.55555556 | E39: =1/9*E3 -> 0.77777778 | F39: =1/9*F3 -> 0.88888889 | G39: =1/9*G3 -> 0.77777778 | H39: =1/9*H3 -> 0.88888889 | I39: =1/9*I3 -> 0.77777778 | J39: =1/9*J3 -> 0.66666667 | ... AH39: =1/9*AH3 -> 0.66666667 | AL39: SRA
A40: IRL | B40: 1.1.1 | C40: =1/9*C4 -> 1 | D40: =1/9*D4 -> 0.44444444 | E40: =1/9*E4 -> 0.33333333 | F40: =1/9*F4 -> 0 | G40: =1/9*G4 -> 0 | H40: =1/9*H4 -> 0 | I40: =1/9*I4 -> 0 | J40: =1/9*J4 -> 0 | ... AH40: =1/9*AH4 -> 0 | AJ40: {=+SUM($C$39:$AH$39*C40:AH40)} -> 1.0617284 | AK40: =+AJ40/COUNTIF(C40:AH40,">0") -> 0.35390947 | AL40: =+_xlfn.XLOOKUP('SRL Test'!AK40,'SRL Transition Model'!$E$4:$E$12,'SRL Transition Model'!$G$4:$G$12,,-1) -> 5
B41: 2.1.1 | C41: =1/9*C5 -> 0.44444444 | D41: =1/9*D5 -> 1 | E41: =1/9*E5 -> 0.33333333 | F41: =1/9*F5 -> 0 | G41: =1/9*G5 -> 0 | H41: =1/9*H5 -> 0 | I41: =1/9*I5 -> 0 | J41: =1/9*J5 -> 0 | ... AH41: =1/9*AH5 -> 0 | AJ41: {=+SUM($C$39:$AH$39*C41:AH41)} -> 1.0617284 | AK41: =+AJ41/COUNTIF(C41:AH41,">0") -> 0.35390947 | AL41: =+_xlfn.XLOOKUP('SRL Test'!AK41,'SRL Transition Model'!$E$4:$E$12,'SRL Transition Model'!$G$4:$G$12,,-1) -> 5
B42: 3.1.2 | C42: =1/9*C6 -> 0.33333333 | D42: =1/9*D6 -> 0 | E42: =1/9*E6 -> 1 | F42: =1/9*F6 -> 0 | G42: =1/9*G6 -> 0 | H42: =1/9*H6 -> 0 | I42: =1/9*I6 -> 0 | J42: =1/9*J6 -> 0 | ... AH42: =1/9*AH6 -> 0 | AJ42: {=+SUM($C$39:$AH$39*C42:AH42)} -> 2.0987654 | AK42: =+AJ42/COUNTIF(C42:AH42,">0") -> 0.29982363 | AL42: =+_xlfn.XLOOKUP('SRL Test'!AK42,'SRL Transition Model'!$E$4:$E$12,'SRL Transition Model'!$G$4:$G$12,,-1) -> 5
B43: 4.1.2 | C43: =1/9*C7 -> 0 | D43: =1/9*D7 -> 0 | E43: =1/9*E7 -> 0.44444444 | F43: =1/9*F7 -> 1 | G43: =1/9*G7 -> 0 | H43: =1/9*H7 -> 0 | I43: =1/9*I7 -> 0 | J43: =1/9*J7 -> 0 | ... AH43: =1/9*AH7 -> 0 | AJ43: {=+SUM($C$39:$AH$39*C43:AH43)} -> 1.2345679 | AK43: =+AJ43/COUNTIF(C43:AH43,">0") -> 0.61728395 | AL43: =+_xlfn.XLOOKUP('SRL Test'!AK43,'SRL Transition Model'!$E$4:$E$12,'SRL Transition Model'!$G$4:$G$12,,-1) -> 7
B44: 4.1.3 | C44: =1/9*C8 -> 0 | D44: =1/9*D8 -> 0 | E44: =1/9*E8 -> 0.44444444 | F44: =1/9*F8 -> 0 | G44: =1/9*G8 -> 1 | H44: =1/9*H8 -> 0 | I44: =1/9*I8 -> 0 | J44: =1/9*J8 -> 0 | ... AH44: =1/9*AH8 -> 0 | AJ44: {=+SUM($C$39:$AH$39*C44:AH44)} -> 1.1234568 | AK44: =+AJ44/COUNTIF(C44:AH44,">0") -> 0.5617284 | AL44: =+_xlfn.XLOOKUP('SRL Test'!AK44,'SRL Transition Model'!$E$4:$E$12,'SRL Transition Model'!$G$4:$G$12,,-1) -> 7
B45: 4.1.5 | C45: =1/9*C9 -> 0 | D45: =1/9*D9 -> 0 | E45: =1/9*E9 -> 0.33333333 | F45: =1/9*F9 -> 0 | G45: =1/9*G9 -> 0 | H45: =1/9*H9 -> 1 | I45: =1/9*I9 -> 0 | J45: =1/9*J9 -> 0 | ... AH45: =1/9*AH9 -> 0 | AJ45: {=+SUM($C$39:$AH$39*C45:AH45)} -> 1.1481481 | AK45: =+AJ45/COUNTIF(C45:AH45,">0") -> 0.57407407 | AL45: =+_xlfn.XLOOKUP('SRL Test'!AK45,'SRL Transition Model'!$E$4:$E$12,'SRL Transition Model'!$G$4:$G$12,,-1) -> 7
B46: 4.1.6 | C46: =1/9*C10 -> 0 | D46: =1/9*D10 -> 0 | E46: =1/9*E10 -> 0.33333333 | F46: =1/9*F10 -> 0 | G46: =1/9*G10 -> 0 | H46: =1/9*H10 -> 0 | I46: =1/9*I10 -> 1 | J46: =1/9*J10 -> 0 | ... AH46: =1/9*AH10 -> 0 | AJ46: {=+SUM($C$39:$AH$39*C46:AH46)} -> 1.037037 | AK46: =+AJ46/COUNTIF(C46:AH46,">0") -> 0.51851852 | AL46: =+_xlfn.XLOOKUP('SRL Test'!AK46,'SRL Transition Model'!$E$4:$E$12,'SRL Transition Model'!$G$4:$G$12,,-1) -> 6
B47: 4.1.8 | C47: =1/9*C11 -> 0 | D47: =1/9*D11 -> 0 | E47: =1/9*E11 -> 0.33333333 | F47: =1/9*F11 -> 0 | G47: =1/9*G11 -> 0 | H47: =1/9*H11 -> 0 | I47: =1/9*I11 -> 0 | J47: =1/9*J11 -> 1 | ... AH47: =1/9*AH11 -> 0 | AJ47: {=+SUM($C$39:$AH$39*C47:AH47)} -> 0.92592593 | AK47: =+AJ47/COUNTIF(C47:AH47,">0") -> 0.46296296 | AL47: =+_xlfn.XLOOKUP('SRL Test'!AK47,'SRL Transition Model'!$E$4:$E$12,'SRL Transition Model'!$G$4:$G$12,,-1) -> 6
B48: 4.2.1 | C48: =1/9*C12 -> 0 | D48: =1/9*D12 -> 0 | E48: =1/9*E12 -> 0 | F48: =1/9*F12 -> 0 | G48: =1/9*G12 -> 0 | H48: =1/9*H12 -> 0 | I48: =1/9*I12 -> 0 | J48: =1/9*J12 -> 0 | ... AH48: =1/9*AH12 -> 0 | AJ48: {=+SUM($C$39:$AH$39*C48:AH48)} -> 0.66666667 | AK48: =+AJ48/COUNTIF(C48:AH48,">0") -> 0.66666667 | AL48: =+_xlfn.XLOOKUP('SRL Test'!AK48,'SRL Transition Model'!$E$4:$E$12,'SRL Transition Model'!$G$4:$G$12,,-1) -> 7 | AN48: =+_xlfn.CONCAT("Samlet SRA = ",AL38) -> Samlet SRA = 6
B49: 4.2.2 | C49: =1/9*C13 -> 0 | D49: =1/9*D13 -> 0 | E49: =1/9*E13 -> 0 | F49: =1/9*F13 -> 0 | G49: =1/9*G13 -> 0 | H49: =1/9*H13 -> 0 | I49: =1/9*I13 -> 0 | J49: =1/9*J13 -> 0 | ... AH49: =1/9*AH13 -> 0 | AJ49: {=+SUM($C$39:$AH$39*C49:AH49)} -> 0.66666667 | AK49: =+AJ49/COUNTIF(C49:AH49,">0") -> 0.66666667 | AL49: =+_xlfn.XLOOKUP('SRL Test'!AK49,'SRL Transition Model'!$E$4:$E$12,'SRL Transition Model'!$G$4:$G$12,,-1) -> 7
B50: 4.2.6 | C50: =1/9*C14 -> 0 | D50: =1/9*D14 -> 0 | E50: =1/9*E14 -> 0.33333333 | F50: =1/9*F14 -> 0 | G50: =1/9*G14 -> 0 | H50: =1/9*H14 -> 0 | I50: =1/9*I14 -> 0 | J50: =1/9*J14 -> 0 | ... AH50: =1/9*AH14 -> 0 | AJ50: {=+SUM($C$39:$AH$39*C50:AH50)} -> 0.92592593 | AK50: =+AJ50/COUNTIF(C50:AH50,">0") -> 0.46296296 | AL50: =+_xlfn.XLOOKUP('SRL Test'!AK50,'SRL Transition Model'!$E$4:$E$12,'SRL Transition Model'!$G$4:$G$12,,-1) -> 6
B51: 4.6.2 | C51: =1/9*C15 -> 0 | D51: =1/9*D15 -> 0 | E51: =1/9*E15 -> 0 | F51: =1/9*F15 -> 0 | G51: =1/9*G15 -> 0 | H51: =1/9*H15 -> 0 | I51: =1/9*I15 -> 0 | J51: =1/9*J15 -> 0 | ... AH51: =1/9*AH15 -> 0 | AJ51: {=+SUM($C$39:$AH$39*C51:AH51)} -> 0.66666667 | AK51: =+AJ51/COUNTIF(C51:AH51,">0") -> 0.66666667 | AL51: =+_xlfn.XLOOKUP('SRL Test'!AK51,'SRL Transition Model'!$E$4:$E$12,'SRL Transition Model'!$G$4:$G$12,,-1) -> 7
B52: 4.7.4 | C52: =1/9*C16 -> 0 | D52: =1/9*D16 -> 0 | E52: =1/9*E16 -> 0 | F52: =1/9*F16 -> 0 | G52: =1/9*G16 -> 0 | H52: =1/9*H16 -> 0 | I52: =1/9*I16 -> 0 | J52: =1/9*J16 -> 0 | ... AH52: =1/9*AH16 -> 0 | AJ52: {=+SUM($C$39:$AH$39*C52:AH52)} -> 0.81481481 | AK52: =+AJ52/COUNTIF(C52:AH52,">0") -> 0.40740741 | AL52: =+_xlfn.XLOOKUP('SRL Test'!AK52,'SRL Transition Model'!$E$4:$E$12,'SRL Transition Model'!$G$4:$G$12,,-1) -> 6
B53: 4.7.5 | C53: =1/9*C17 -> 0 | D53: =1/9*D17 -> 0 | E53: =1/9*E17 -> 0.33333333 | F53: =1/9*F17 -> 0 | G53: =1/9*G17 -> 0 | H53: =1/9*H17 -> 0 | I53: =1/9*I17 -> 0 | J53: =1/9*J17 -> 0 | ... AH53: =1/9*AH17 -> 0 | AJ53: {=+SUM($C$39:$AH$39*C53:AH53)} -> 0.92592593 | AK53: =+AJ53/COUNTIF(C53:AH53,">0") -> 0.46296296 | AL53: =+_xlfn.XLOOKUP('SRL Test'!AK53,'SRL Transition Model'!$E$4:$E$12,'SRL Transition Model'!$G$4:$G$12,,-1) -> 6
B54: 4.7.6 | C54: =1/9*C18 -> 0 | D54: =1/9*D18 -> 0 | E54: =1/9*E18 -> 0.33333333 | F54: =1/9*F18 -> 0 | G54: =1/9*G18 -> 0 | H54: =1/9*H18 -> 0 | I54: =1/9*I18 -> 0 | J54: =1/9*J18 -> 0 | ... AH54: =1/9*AH18 -> 0 | AJ54: {=+SUM($C$39:$AH$39*C54:AH54)} -> 0.92592593 | AK54: =+AJ54/COUNTIF(C54:AH54,">0") -> 0.46296296 | AL54: =+_xlfn.XLOOKUP('SRL Test'!AK54,'SRL Transition Model'!$E$4:$E$12,'SRL Transition Model'!$G$4:$G$12,,-1) -> 6
B55: 4.7.9 | C55: =1/9*C19 -> 0 | D55: =1/9*D19 -> 0 | E55: =1/9*E19 -> 0.33333333 | F55: =1/9*F19 -> 0 | G55: =1/9*G19 -> 0 | H55: =1/9*H19 -> 0 | I55: =1/9*I19 -> 0 | J55: =1/9*J19 -> 0 | ... AH55: =1/9*AH19 -> 0 | AJ55: {=+SUM($C$39:$AH$39*C55:AH55)} -> 0.92592593 | AK55: =+AJ55/COUNTIF(C55:AH55,">0") -> 0.46296296 | AL55: =+_xlfn.XLOOKUP('SRL Test'!AK55,'SRL Transition Model'!$E$4:$E$12,'SRL Transition Model'!$G$4:$G$12,,-1) -> 6
B56: 4.10.10 | C56: =1/9*C20 -> 0 | D56: =1/9*D20 -> 0 | E56: =1/9*E20 -> 0 | F56: =1/9*F20 -> 0 | G56: =1/9*G20 -> 0 | H56: =1/9*H20 -> 0 | I56: =1/9*I20 -> 0 | J56: =1/9*J20 -> 0 | ... AH56: =1/9*AH20 -> 0 | AJ56: {=+SUM($C$39:$AH$39*C56:AH56)} -> 0.66666667 | AK56: =+AJ56/COUNTIF(C56:AH56,">0") -> 0.66666667 | AL56: =+_xlfn.XLOOKUP('SRL Test'!AK56,'SRL Transition Model'!$E$4:$E$12,'SRL Transition Model'!$G$4:$G$12,,-1) -> 7
B57: 4.10.12 | C57: =1/9*C21 -> 0 | D57: =1/9*D21 -> 0 | E57: =1/9*E21 -> 0 | F57: =1/9*F21 -> 0 | G57: =1/9*G21 -> 0 | H57: =1/9*H21 -> 0 | I57: =1/9*I21 -> 0 | J57: =1/9*J21 -> 0 | ... AH57: =1/9*AH21 -> 0 | AJ57: {=+SUM($C$39:$AH$39*C57:AH57)} -> 0.96296296 | AK57: =+AJ57/COUNTIF(C57:AH57,">0") -> 0.48148148 | AL57: =+_xlfn.XLOOKUP('SRL Test'!AK57,'SRL Transition Model'!$E$4:$E$12,'SRL Transition Model'!$G$4:$G$12,,-1) -> 6
B58: 4.10.13 | C58: =1/9*C22 -> 0 | D58: =1/9*D22 -> 0 | E58: =1/9*E22 -> 0.44444444 | F58: =1/9*F22 -> 0 | G58: =1/9*G22 -> 0 | H58: =1/9*H22 -> 0 | I58: =1/9*I22 -> 0 | J58: =1/9*J22 -> 0 | ... AH58: =1/9*AH22 -> 0 | AJ58: {=+SUM($C$39:$AH$39*C58:AH58)} -> 1.0123457 | AK58: =+AJ58/COUNTIF(C58:AH58,">0") -> 0.50617284 | AL58: =+_xlfn.XLOOKUP('SRL Test'!AK58,'SRL Transition Model'!$E$4:$E$12,'SRL Transition Model'!$G$4:$G$12,,-1) -> 6
B59: 4.13.3 | C59: =1/9*C23 -> 0 | D59: =1/9*D23 -> 0 | E59: =1/9*E23 -> 0.44444444 | F59: =1/9*F23 -> 0 | G59: =1/9*G23 -> 0 | H59: =1/9*H23 -> 0 | I59: =1/9*I23 -> 0 | J59: =1/9*J23 -> 0 | ... AH59: =1/9*AH23 -> 0 | AJ59: {=+SUM($C$39:$AH$39*C59:AH59)} -> 0.90123457 | AK59: =+AJ59/COUNTIF(C59:AH59,">0") -> 0.45061728 | AL59: =+_xlfn.XLOOKUP('SRL Test'!AK59,'SRL Transition Model'!$E$4:$E$12,'SRL Transition Model'!$G$4:$G$12,,-1) -> 6
B60: 5.2.1 | C60: =1/9*C24 -> 0 | D60: =1/9*D24 -> 0 | E60: =1/9*E24 -> 0 | F60: =1/9*F24 -> 0 | G60: =1/9*G24 -> 0 | H60: =1/9*H24 -> 0 | I60: =1/9*I24 -> 0 | J60: =1/9*J24 -> 0 | ... AH60: =1/9*AH24 -> 0 | AJ60: {=+SUM($C$39:$AH$39*C60:AH60)} -> 0.74074074 | AK60: =+AJ60/COUNTIF(C60:AH60,">0") -> 0.37037037 | AL60: =+_xlfn.XLOOKUP('SRL Test'!AK60,'SRL Transition Model'!$E$4:$E$12,'SRL Transition Model'!$G$4:$G$12,,-1) -> 5
...
